Workbook

Sheet Eval 1
A1: Activité intégrative : itération 1
M2: Acquis évalués : | N2: AA 1 | O2: AA 2 | P2: AA 3 | Q2: AA 4 | R2: AA5
A3: Nom et prénom : | C3: Votre nom et Votre prénom | G3: Commande d'exécution de l'application : | K3: gradle run --args="--config-file salon.ini" | M3: Statut (Observé=1, Pas observé=0) | N3: =IF($O$5=$N$5,TRUNC($N$14/$O$14),0) -> 0 | O3: =IF($O$5=$N$5,TRUNC($N$20/$O$20),0) -> 1 | P3: =IF($O$5=$N$5,TRUNC($N$27/$O$27),0) -> 1 | Q3: =IF($O$5=$N$5,TRUNC($N$33/$O$33),0) -> 1 | R3: =IF($O$5=$N$5,TRUNC($N$39/$O$39),0) -> 0
A4: Matricule : | C4: Votre matricule
A5: Préalable | K5: Observé (oui=1, non = 0) | L5: Justification de l'étudiant | M5: Total préalable | N5: =SUM($K$7:$K$12) -> 6 | O5: 6 | Q5: Retour de l'enseignant
A6: Tous ces éléments sont à observer pour que le travail soit évaluable
A7: Le projet Java ou la solution C# ont été mis à disposition à temps, selon les modalités prévues par l'énoncé (délais, règles relatives au dépôt distant, etc.) | K7: 1
A8: L'auto-évaluation est de qualité | K8: =IF(N8<=O8,1,0) -> 1 | M8: justifications manquantes ou imprécises | N8: 1 | O8: 3
A9: Le projet Java cible le JDK 17 et Gradle 8.+ Le projet C# cible .NET 6 et Avalonia 11+ | K9: 1
A10: Le dépôt distant peut être construit sans erreurs de compilation. Au besoin l'outil de construction résout les dépendances tierces. | K10: 1
A11: L'application utilise des ressources externes pour lire et sauver les données demandées. Ces ressources externes respectent les contraintes de l'énoncé (type de ressource, localisation, etc.) | K11: 1
A12: Les fonctionnalités requises sont implémentées et sufisamment de tests d'acceptation réussissent | K12: =IF(N12<=O12,1,0) -> 1 | L12: Toutes les us ont été implémentées | M12: TA non-observés : | N12: 0 | O12: 3
A14: Acquis 1 : Concevoir une solution selon les principes de l'orienté objet | K14: Observé | M14: Total Acquis 1 | N14: =SUM($K$16:$K$19) -> 3 | O14: 4
A15: Seuil de réussite (tous sont à valider pour obtenir l'acquis)
A16: Les méthodes sont peu complexes [ ] au plus 1 alerte NCSS dans les projets domains, presentations et infrastructures [ ] au plus 1 alerte CC dans les projets domains, presentations et infrastructures [ ] au plus 1 alerte TooManyParameter dans les projets domains, presentations et infrastructures | K16: 0 | L16: Aucune alerte de ces types est présente au sein de cette iteration 1
A17: Déclarer des types avec une cohésion forte [ ] au plus 1 alerte LackOfCohesion dans les projets domains, presentations et infrastructures [ ] au plus 1 alerte TooManyFields max dans les projets domains, presentations et infrastructures [ ] au plus 1 alerte TooManyMethods max dans les projets domains, presentations et infrastructures | K17: 1 | L17: Alerte lackOfCohesion : presentations.IniConfiguration Reader (IniConfigurationReader begins at 10 ends at 184) Alerte lackOfCohesion : views.ConsoleThermometerViews (ConsoleThermometerView begins at 7 ends at 28) | Q17: ClassLackingOfCohesion (violation count: 2) Type: IniConfigurationReader begins at 10 ends at 182 This class members does not seem to form a cohesive set.
A18: Déclarer des types avec un couplage faible [ ] 1 alerte AvoidNonPrivateInstanceField dans les projets domains, presentations et infrastructures [ ] 1 alerte CouplingBetweenObject dans les projets domains, presentations et infrastructures [ ] 1 alerte LooseCoupling max. dans les projets domains, presentations et infrastructures | K18: 1 | L18: Aucune alerte de ces types est présente au sein de cette iteration 1
A19: Les types sont logiquement regroupés [ ] Pas d'alertes ArchUnit | K19: 1 | L19: Aucune alerte ArchUnit | Q19: System.out.print ailleurs que dans le sous-projet views
A20: Acquis 2 : Programmer en exploitant les spécificités d'un langage de programmation | M20: Total Acquis 2 | N20: =SUM($K$22:$K$26) -> 5 | O20: 5
A21: Seuil de réussite (tous sont à valider pour obtenir l'acquis)
A22: Le code respecte les convention d'écriture du langage [ ] 5 alertes liées aux conventions d'écriture max. | K22: 1 | L22: Il y'a 0 alertes liées aux conventions d'écriture. | Q22: UnusedFormalParameter (violation count: 1) Type: Sonde begins at 81 ends at 81 Avoid unused method parameters such as 'currentJalonIndex'. SystemPrintln (violation count: 6) Type: TemperatureAlert begins at 36 ends at 36 System.out.println is used Type: TemperatureAlert begins at 43 ends at 43 System.out.printf is used Type: ThermometerPresenter begins at 39 ends at 39 System.out.print is used Type: IniConfigurationReader begins at 160 ends at 160 System.err.println is used
A23: Le code exploite les pipeline de collections (stream en Java, Linq en C#) [ ] Au moins une utilisation pertinente de pipeline dans le code métier ou applicatif | K23: 1 | L23: j'utilise un stream dans la methode calculateAverageMeasurement présente dans domains.Agregateur ligne 42 a 57
A24: Le code exploite la notion d'enregistrements [ ] Au moins un DTO ou Arguments d'événements est défini par un enregistrement | K24: 1 | L24: j'ai 3 Record dans le module domains : Thermometer, Jalon, Mesure
A25: Le code exploite adéquatement les génériques [ ] Définition d'au moins un type générique [ ] Le type générique est utilisé avec deux arguments de type différents. | K25: 1 | L25: indiquez le nom du fichier où vous déclarez un type générique. Indiquez vos exemples d'utilisation en mentionnant le nom de fichier et la ligne.
A26: Le code exploite les références de méthode [ ] Java déclaration d'au moins un membre de type interface fonctionnelle et initialisation [ ] C# déclaration d'au moins un membre event | K26: 1 | L26: indiquez le nom du fichier où vous déclarez une membre auquel vous affectez des références de méthode ou expressions lamdba
A27: Acquis 3 : Exploiter des ressources externes | M27: Total Acquis 3 | N27: =SUM($K$29:$K32) -> 4 | O27: 4
A28: Seuil de réussite (tous sont à valider pour obtenir l'acquis)
A29: Les ressources acquises sont effectivement libérées [ ] Pas d'alerte AvoidFileStream [ ] Pas d'alerte UseTryWithResources [ ] Pas d'alerte CloseResource | K29: 1 | L29: je n'ai aucune alerte a propos de ces types d'alertes
A30: Les exceptions spécifiques aux ressources utilisées sont attrapées et traitées [ ] Pas d'alerte EmptyCatchBlock [ ] Pas d'alerte EmptyFinallyBlock [ ] Pas d'alerte EmptyTryBlock [ ] Pas d'alerte AvoidRethrowingException [ ] Pas d'alerte AvoidRethrowingNewInstanceOfTheSameException | K30: 1 | L30: je n'ai aucune alerte a propos de ces types d'alertes
A31: Les transactions manuelles sont correctement mises en places aux endroits nécessaires [ ] La transaction est commencée [ ] La transaction est validée en cas de succès (commit) [ ] La transaction est annulée en cas d'échec (rollback) [ ] La transaction est utilisée pour soumettre plusieurs requêtes modifiant la BD | K31: 1 | L31: indiquez le nom du fichier et la ligne à partir de laquelle vous utilisez adéquatement une transaction. En cas d'indicateur non-validé pour l'exemple donné, signaler les. Ex: ma transaction est utilisée pour soumettre une seule requête SQL.
A32: Le cas échéant les requêtes SQL sont paramétrés adéquatement [ ] les arguments des requêtes SQL utilisent les méthodes adéquates pour être injectés dans la requête. [ ] les types des arguments sont adéquat par rapport au type de la colonne et inversement. | K32: 1 | L32: indiquez le nom du fichier et les lignes où vous paramétrez vos requêtes SQL. En cas d'indicateur non-validé, indiquez-le Ex: j'ai paramétré une colonne de type VARCHAR avec la méthode setString, mais son argument est une datetime.
A33: Acquis 4 : Tester en intégration | M33: Total Acquis 4 | N33: =SUM($K$35:$K39) -> 4 | O33: 4
A34: Seuil de réussite (tous sont à valider pour obtenir l'acquis)
A35: Des ressources spécifiques à l'environnement de test sont utilisées | K35: 1 | L35: mon fichier de test se trouve dans : App/src/test/ressources et le fichier s'appelle LivingRoomTest.ini et mes tests sont effectué dans test
A36: Les tests valident le happy path et au moins un cas dégradé | K36: 1 | L36: test happyPath : get_whenKeyExists_returnsValue test cas dégradé : get_whenKeyDoesNotExist_returnsNull dans App/src/test/IniConfigurationReaderTests
A37: Les tests réussissent sans adaptations | K37: 1
A38: Les tests sont rejouables sans modifications extérieures | K38: 1
A39: Acquis 5 : Tester en isolation | M39: Total Acquis 5 | N39: =SUM($K$41:$K44) -> 3 | O39: 4
A40: Seuil de réussite (tous sont à valider pour obtenir l'acquis)
A41: Les instructions des projets domains et présentations sont couvertes à 80% par des tests unitaires | K41: 0 | L41: domains : 94% presentations : 27% infrastructures = 95% | Q41: Manque de couverture de test : couverture de la partie domains = 94.14414414414415%% - couverture de la partie presentations = 27.06766917293233%%
...

Sheet Eval 2
A1: Activité intégrative : itération 2
M2: Acquis évalués : | N2: AA 1 | O2: AA 2 | P2: AA 3 | Q2: AA 4 | R2: AA5
A3: Nom et prénom : | C3: Votre nom et Votre prénom | G3: Commande d'exécution de l'application : | K3: ex: dotnet run -- --config-file config.ini | M3: Statut (Observé=1, Pas observé=0) | N3: =IF($O$5=$N$5,TRUNC($N$14/$O$14),0) -> 0 | O3: =IF($O$5=$N$5,TRUNC($N$20/$O$20),0) -> 0 | P3: =IF($O$5=$N$5,TRUNC($N$27/$O$27),0) -> 1 | Q3: =IF($O$5=$N$5,TRUNC($N$33/$O$33),0) -> 1 | R3: =IF($O$5=$N$5,TRUNC($N$39/$O$39),0) -> 1
A4: Matricule : | C4: Votre matricule
A5: Préalable | K5: Observé (oui=1, non = 0) | L5: Justification de l'étudiant | M5: Total préalable | N5: =SUM($K$7:$K$12) -> 6 | O5: 6 | Q5: Retour de l'enseignant
A6: Tous ces éléments sont à observer pour que le travail soit évaluable
A7: Le projet Java ou la solution C# ont été mis à disposition à temps, selon les modalités prévues par l'énoncé (délais, règles relatives au dépôt distant, etc.) | K7: 1
A8: L'auto-évaluation est de qualité | K8: =IF(N8<=O8,1,0) -> 1 | M8: justifications manquantes ou imprécises | N8: 0 | O8: 3
A9: Le projet Java cible le JDK 17 et Gradle 8.+ Le projet C# cible .NET 6 et Avalonia 11+ | K9: 1
A10: Le dépôt distant peut être construit sans erreurs de compilation. Au besoin l'outil de construction résout les dépendances tierces. | K10: 1 | Q10: Renomme le editorconfig en .editorconfig pour avoir moins d'alerte et les bonnes
A11: L'application utilise des ressources externes pour lire et sauver les données demandées. Ces ressources externes respectent les contraintes de l'énoncé (type de ressource, localisation, etc.) | K11: 1
A12: Les fonctionnalités requises sont implémentées et sufisamment de tests d'acceptation réussissent | K12: =IF(N12<=O12,1,0) -> 1 | L12: Toute les fonctionnalités ont été implémenter | M12: TA non-observés : | N12: 0 | O12: 3 | Q12: Pour avoir les messages d'erreur lorsque tu fais dotnet run, il faut changer dans le csproj de App la propriété OutputType et la mettre à Exe La commande à exécuter n'a pas été mise en K3
A14: Acquis 1 : Concevoir une solution selon les principes de l'orienté objet | K14: Observé | M14: Total Acquis 1 | N14: =SUM($K$16:$K$19) -> 2 | O14: 4
A15: Seuil de réussite (tous sont à valider pour obtenir l'acquis)
A16: Les méthodes sont peu complexes [ ] au plus 1 alerte NCSS dans les projets domains, presentations et infrastructures [ ] au plus 1 alerte CC dans les projets domains, presentations et infrastructures [ ] au plus 1 alerte TooManyParameter dans les projets domains, presentations et infrastructures | K16: 1 | L16: Aucune alerte de ces types
A17: Déclarer des types avec une cohésion forte [ ] au plus 1 alerte LackOfCohesion dans les projets domains, presentations et infrastructures [ ] au plus 1 alerte TooManyFields max dans les projets domains, presentations et infrastructures [ ] au plus 1 alerte TooManyMethods max dans les projets domains, presentations et infrastructures | K17: 0 | L17: 3 alertes LackOfCohesion : dans les classes Thermometer,ThermometerAlert, ThermometerMeasure dans le module domains | Q17: Configuration.cs(3,5): warning HE0001: Configuration does not define a cohesive set. CKCohesion should be > 1,1. Actual 8. Thermometer.cs(3,1): warning HE0001: Thermometer does not define a cohesive set. CKCohesion should be > 1,1. Actual 8. ThermometerAlert.cs(3,1): warning HE0001: ThermometerAlert does not define a cohesive set. CKCohesion should be > 1,1. Actual 1,75. ThermometerMeasure.cs(3,1): warning HE0001: ThermometerMeasure does not define a cohesive set. CKCohesion should be > 1,1. Actual 1,75.
A18: Déclarer des types avec un couplage faible [ ] 1 alerte AvoidNonPrivateInstanceField dans les projets domains, presentations et infrastructures [ ] 1 alerte CouplingBetweenObject dans les projets domains, presentations et infrastructures [ ] 1 alerte LooseCoupling max. dans les projets domains, presentations et infrastructures | K18: 0 | L18: Aucune alerte de ces types | Q18: Thermometer.cs(3,1): warning HE0004: Type Thermometer leaks 2 non private instance fields Configuration.cs(5,9): warning HE0009: Avoid to expose concrete type IConfigurationReader.cs(7,25): warning HE0009: Avoid to expose concrete type Thermometer.cs(8,5): warning HE0009: Avoid to expose concrete type CsvConfigurationReader.cs(11,5): warning HE0009: Avoid to expose concrete type CsvConfigurationReader.cs(53,5): warning HE0009: Avoid to expose concrete type IniConfigurationReader.cs(10,9): warning HE0009: Avoid to expose concrete type IniConfigurationReader.cs(19,36): warning HE0009: Avoid to expose concrete type IniConfigurationReader.cs(76,9): warning HE0009: Avoid to expose concrete type IniConfigurationReader.cs(90,9): warning HE0009: Avoid to expose concrete type IniConfigurationReader.cs(101,9): warning HE0009: Avoid to expose concrete type MainPresenter.cs(9,9): warning HE0009: Avoid to expose concrete type MainPresenter.cs(10,9): warning HE0009: Avoid to expose concrete type MainPresenter.cs(12,9): warning HE0009: Avoid to expose concrete type
A19: Les types sont logiquement regroupés [ ] Pas d'alertes ArchUnit | K19: 1 | L19: Aucune alertes Archunit a signalé
A20: Acquis 2 : Programmer en exploitant les spécificités d'un langage de programmation | M20: Total Acquis 2 | N20: =SUM($K$23:$K$26) -> 3 | O20: 4
A21: Seuil de réussite (tous sont à valider pour obtenir l'acquis)
A22: Le code respecte les convention d'écriture du langage [ ] 5 alertes liées aux conventions d'écriture max. | K22: 0 | L22: Toutes les conventions d'écriture du language (c#) ont été respectées | Q22: Thermometer.cs(5,19): warning CS8618: Le propriété 'Name' non-nullable doit contenir une valeur non-null lors de la fermeture du constructeur. Envisagez de déclarer le propriété comme nullable. Thermometer.cs(6,19): warning CS8618: Le champ 'DateTimeFormat' non-nullable doit contenir une valeur non-null lors de la fermeture du constructeur. Envisagez de déclarer le champ comme nullable. Thermometer.cs(7,19): warning CS8618: Le champ 'TemperatureFormat' non-nullable doit contenir une valeur non-null lors de la fermeture du constructeur. Envisagez de déclarer le champ comme nullable. ThermometerAlert.cs(6,19): warning CS8618: Le propriété 'ThermometerName' non-nullable doit contenir une valeur non-null lors de la fermeture du constructeur. Envisagez de déclarer le propriété comme nullable. ThermometerMeasure.cs(5,19): warning CS8618: Le propriété 'ThermometerName' non-nullable doit contenir une valeur non-null lors de la fermeture du constructeur. Envisagez de déclarer le propriété comme nullable. ThermometerMeasure.cs(7,19): warning CS8618: Le propriété 'MeasureType' non-nullable doit contenir une valeur non-null lors de la fermeture du constructeur. Envisagez de déclarer le propriété comme nullable. IniConfigurationReader.cs(21,37): warning CS8600: Conversion de littéral ayant une valeur null ou d'une éventuelle valeur null en type non-nullable. IniConfigurationReader.cs(23,28): warning CS8600: Conversion de littéral ayant une valeur null ou d'une éventuelle valeur null en type non-nullable. IniConfigurationReader.cs(25,39): warning CS8601: Existence possible d'une assignation de référence null. IniConfigurationReader.cs(71,20): warning CS8603: Existence possible d'un retour de référence null. MainPresenter.cs(39,40): warning CS8601: Existence possible d'une assignation de référence null. MainPresenter.cs(15,16): warning CS8618: Le champ '_selectedThermometerName' non-nullable doit contenir une valeur non-null lors de la fermeture du constructeur. Envisagez de déclarer le champ comme nullable.
A23: Le code exploite les pipeline de collections (stream en Java, Linq en C#) [ ] Au moins une utilisation pertinente de pipeline dans le code métier ou applicatif | K23: 1 | L23: j'utilise les linq dans ma classe MainPresenter dans le module presentations plus précisement dans la methode UpdateMeasurements
A24: Le code exploite la notion d'enregistrements [ ] Au moins un DTO ou Arguments d'événements est défini par un enregistrement | K24: 0 | L24: / | Q24: Il n'y a aucun record
A25: Le code exploite adéquatement les génériques [ ] Définition d'au moins un type générique [ ] Le type générique est utilisé avec deux arguments de type différents. | K25: 1 | L25: indiquez le nom du fichier où vous déclarez un type générique. Indiquez vos exemples d'utilisation en mentionnant le nom de fichier et la ligne.
A26: Le code exploite les références de méthode [ ] Java déclaration d'au moins un membre de type interface fonctionnelle et initialisation [ ] C# déclaration d'au moins un membre event | K26: 1 | L26: indiquez le nom du fichier où vous déclarez une membre auquel vous affectez des références de méthode ou expressions lamdba
A27: Acquis 3 : Exploiter des ressources externes | M27: Total Acquis 3 | N27: =SUM($K$29:$K32) -> 4 | O27: 4
A28: Seuil de réussite (tous sont à valider pour obtenir l'acquis)
A29: Les ressources acquises sont effectivement libérées [ ] Pas d'alerte AvoidFileStream [ ] Pas d'alerte UseTryWithResources [ ] Pas d'alerte CloseResource | K29: 1 | L29: Aucune alerte de ces types n'est présente | Q29: IniConfigurationReader.cs(16,28): warning IDISP004: Don't ignore created Idisposable
A30: Les exceptions spécifiques aux ressources utilisées sont attrapées et traitées [ ] Pas d'alerte EmptyCatchBlock [ ] Pas d'alerte EmptyFinallyBlock [ ] Pas d'alerte EmptyTryBlock [ ] Pas d'alerte AvoidRethrowingException [ ] Pas d'alerte AvoidRethrowingNewInstanceOfTheSameException | K30: 1 | L30: Aucune alerte de ces types n'est présente
A31: Les transactions manuelles sont correctement mises en places aux endroits nécessaires [ ] La transaction est commencée [ ] La transaction est validée en cas de succès (commit) [ ] La transaction est annulée en cas d'échec (rollback) [ ] La transaction est utilisée pour soumettre plusieurs requêtes modifiant la BD | K31: 1 | L31: indiquez le nom du fichier et la ligne à partir de laquelle vous utilisez adéquatement une transaction. En cas d'indicateur non-validé pour l'exemple donné, signaler les. Ex: ma transaction est utilisée pour soumettre une seule requête SQL.
A32: Le cas échéant les requêtes SQL sont paramétrés adéquatement [ ] les arguments des requêtes SQL utilisent les méthodes adéquates pour être injectés dans la requête. [ ] les types des arguments sont adéquat par rapport au type de la colonne et inversement. | K32: 1 | L32: indiquez le nom du fichier et les lignes où vous paramétrez vos requêtes SQL. En cas d'indicateur non-validé, indiquez-le Ex: j'ai paramétré une colonne de type VARCHAR avec la méthode setString, mais son argument est une datetime.
A33: Acquis 4 : Tester en intégration | M33: Total Acquis 4 | N33: =SUM($K$35:$K39) -> 4 | O33: 4
A34: Seuil de réussite (tous sont à valider pour obtenir l'acquis)
A35: Des ressources spécifiques à l'environnement de test sont utilisées | K35: 1 | L35: j'utilise deux fichiers pour mes tests dans le module Stas.Monitor.Presentations.Tests , les fichiers sont fakeAlerte et fakeMesures | Q35: Bizarre de ne pas plutôt les avoir mis dans Infrastructure avec un fichier de test.ini
A36: Les tests valident le happy path et au moins un cas dégradé | K36: 1 | L36: HappyPath_UpdateMeasurements_ShouldLoadCorrectEvents pour le happy path et le cas dégradé : DegradedPath_MissingThermometer_ShouldNotLoadDataForMissingThermometer Dans le module Stas.Monitor.App.tests dans MainPresenterIntregrationTests
A37: Les tests réussissent sans adaptations | K37: 1
A38: Les tests sont rejouables sans modifications extérieures | K38: 1
A39: Acquis 5 : Tester en isolation | M39: Total Acquis 5 | N39: =SUM($K$41:$K44) -> 4 | O39: 4
A40: Seuil de réussite (tous sont à valider pour obtenir l'acquis)
A41: Les instructions des projets domains et présentations sont couvertes à 80% par des tests unitaires | K41: 1 | L41: domains : 94% et Presentations : 85% | Q41: Manque de couverture de test : couverture de la partie domains = 94% - couverture de la partie presentations = 85%
...

Sheet Eval 3
A1: Activité intégrative : itération 3
M2: Acquis évalués : | N2: AA 1 | O2: AA 2 | P2: AA 3 | Q2: AA 4 | R2: AA5
A3: Nom et prénom : | C3: Bouzia Badr | G3: Commande d'exécution de l'application : | K3: gradle run --args="--config-file salon.ini" | M3: Statut (Observé=1, Pas observé=0) | N3: =IF($O$5=$N$5,TRUNC($N$14/$O$14),0) -> 0 | O3: =IF($O$5=$N$5,TRUNC($N$20/$O$20),0) -> 0 | P3: =IF($O$5=$N$5,TRUNC($N$27/$O$27),0) -> 0 | Q3: =IF($O$5=$N$5,TRUNC($N$33/$O$33),0) -> 0 | R3: =IF($O$5=$N$5,TRUNC($N$39/$O$39),0) -> 0
A4: Matricule : | C4: Q220251
A5: Préalable | K5: Observé (oui=1, non = 0) | L5: Justification de l'étudiant | M5: Total préalable | N5: =SUM($K$7:$K$12) -> 5 | O5: 6 | Q5: Retour de l'enseignant
A6: Tous ces éléments sont à observer pour que le travail soit évaluable
A7: Le projet Java ou la solution C# ont été mis à disposition à temps, selon les modalités prévues par l'énoncé (délais, règles relatives au dépôt distant, etc.) | K7: 1
A8: L'auto-évaluation est de qualité | K8: =IF(N8<=O8,1,0) -> 1 | M8: justifications manquantes ou imprécises | N8: 0 | O8: 3
A9: Le projet Java cible le JDK 17 et Gradle 8.+ Le projet C# cible .NET 6 et Avalonia 11+ | K9: 1
A10: Le dépôt distant peut être construit sans erreurs de compilation. Au besoin l'outil de construction résout les dépendances tierces. | K10: 1
A11: L'application utilise des ressources externes pour lire et sauver les données demandées. Ces ressources externes respectent les contraintes de l'énoncé (type de ressource, localisation, etc.) | K11: 1
A12: Les fonctionnalités requises sont implémentées et sufisamment de tests d'acceptation réussissent | K12: =IF(N12<=O12,1,0) -> 0 | L12: Toutes les fonctionnalités ont été implémentées. | M12: TA non-observés : | N12: 4 | O12: 3 | Q12: AI-Java-6 : TA4 AI-Java-7 : TA1, TA2, TA3
A14: Acquis 1 : Concevoir une solution selon les principes de l'orienté objet | K14: Observé | M14: Total Acquis 1 | N14: =SUM($K$16:$K$19) -> 4 | O14: 4
A15: Seuil de réussite (tous sont à valider pour obtenir l'acquis)
A16: Les méthodes sont peu complexes [ ] au plus 1 alerte NCSS dans les projets domains, presentations et infrastructures [ ] au plus 1 alerte CC dans les projets domains, presentations et infrastructures [ ] au plus 1 alerte TooManyParameter dans les projets domains, presentations et infrastructures | K16: 1 | L16: Aucune de ces alertes dans le projet
A17: Déclarer des types avec une cohésion forte [ ] au plus 1 alerte LackOfCohesion dans les projets domains, presentations et infrastructures [ ] au plus 1 alerte TooManyFields max dans les projets domains, presentations et infrastructures [ ] au plus 1 alerte TooManyMethods max dans les projets domains, presentations et infrastructures | K17: 1 | L17: Une alerte lack of cohesion dans : domains/MesureDataMapper mais il n'est a pas prendre en compte car au labo vous l'avez annulé. Une alerte TooManyFields dans domains/TemperatureAlert | Q17: ClassLackingOfCohesion in stas.thermometer.domains.MesureDataMapper.None at line 5 until line 79 : This class members does not seem to form a cohesive set. TooManyFields in stas.thermometer.domains.TemperatureAlert.None at line 5 until line 116 : Too many fields
A18: Déclarer des types avec un couplage faible [ ] 1 alerte AvoidNonPrivateInstanceField dans les projets domains, presentations et infrastructures [ ] 1 alerte CouplingBetweenObject dans les projets domains, presentations et infrastructures [ ] 1 alerte LooseCoupling max. dans les projets domains, presentations et infrastructures | K18: 1 | L18: Aucune de ces alertes dans le projet
A19: Les types sont logiquement regroupés [ ] Pas d'alertes ArchUnit | K19: 1 | L19: Tous les tests ArchUnit passe avec succès.
A20: Acquis 2 : Programmer en exploitant les spécificités d'un langage de programmation | M20: Total Acquis 2 | N20: =SUM($K$23:$K$26) -> 4 | O20: 4
A21: Seuil de réussite (tous sont à valider pour obtenir l'acquis)
A22: Le code respecte les convention d'écriture du langage [ ] 5 alertes liées aux conventions d'écriture max. | K22: 1 | L22: domains/TemperatureAlert begins at 50 ends at 50 Avoid using Literals in Conditional Statements domains/TemperatureAlert begins at 85 ends at 85 Avoid using Literals in Conditional Statements
A23: Le code exploite les pipeline de collections (stream en Java, Linq en C#) [ ] Au moins une utilisation pertinente de pipeline dans le code métier ou applicatif | K23: 1 | L23: j'utilise un stream dans domains/AgregateurHumidity ligne 25 a 27 et dans domains/Agregateur ligne 36 a 38
A24: Le code exploite la notion d'enregistrements [ ] Au moins un DTO ou Arguments d'événements est défini par un enregistrement | K24: 1 | L24: j'ai un dto dans domains/Mesure et dans domains/Alert et j'en ai d'autres mais ce sont les principales ceux cités.(les autres: domains/jalons , domains/AggregateurConfig et domains/AggregateurConfigHumidity
A25: Le code exploite adéquatement les génériques [ ] Définition d'au moins un type générique [ ] Le type générique est utilisé avec deux arguments de type différents. | K25: 1 | L25: j'utilise un type générique (T)dans domains/MesureDataMapper et le type générique est utilisé avec deux types arguments de types différents qui sont les suivant : Mesure et Alert
A26: Le code exploite les références de méthode [ ] Java déclaration d'au moins un membre de type interface fonctionnelle et initialisation [ ] C# déclaration d'au moins un membre event | K26: 1 | L26: j'ai déclarer une interface fonctionnelle dans domains/DataBaseAction
A27: Acquis 3 : Exploiter des ressources externes | M27: Total Acquis 3 | N27: =SUM($K$29:$K32) -> 4 | O27: 4
A28: Seuil de réussite (tous sont à valider pour obtenir l'acquis)
A29: Les ressources acquises sont effectivement libérées [ ] Pas d'alerte AvoidFileStream [ ] Pas d'alerte UseTryWithResources [ ] Pas d'alerte CloseResource | K29: 1 | L29: Aucune de ces alertes dans le projet
A30: Les exceptions spécifiques aux ressources utilisées sont attrapées et traitées [ ] Pas d'alerte EmptyCatchBlock [ ] Pas d'alerte EmptyFinallyBlock [ ] Pas d'alerte EmptyTryBlock [ ] Pas d'alerte AvoidRethrowingException [ ] Pas d'alerte AvoidRethrowingNewInstanceOfTheSameException | K30: 1 | L30: Aucune de ces alertes dans le projet
A31: Les transactions manuelles sont correctement mises en places aux endroits nécessaires [ ] La transaction est commencée [ ] La transaction est validée en cas de succès (commit) [ ] La transaction est annulée en cas d'échec (rollback) [ ] La transaction est utilisée pour soumettre plusieurs requêtes modifiant la BD | K31: 1 | L31: Dans domains/MesureDataMapper ( j'ai precisé le rollback pour etre sur malgré que peut etre que les ressources soit fermer inplicitement par le try with ressource) rollback : ligne 18 , commit : ligne 21
A32: Le cas échéant les requêtes SQL sont paramétrés adéquatement [ ] les arguments des requêtes SQL utilisent les méthodes adéquates pour être injectés dans la requête. [ ] les types des arguments sont adéquat par rapport au type de la colonne et inversement. | K32: 1 | L32: Dans domains/MesureDataMapper : tous a éte parametrés correctement
A33: Acquis 4 : Tester en intégration | M33: Total Acquis 4 | N33: =SUM($K$35:$K39) -> 4 | O33: 4
A34: Seuil de réussite (tous sont à valider pour obtenir l'acquis)
A35: Des ressources spécifiques à l'environnement de test sont utilisées | K35: 1 | L35: base de données derby a la racine du projet (DbTest) et infrastructures/src/test/resources/LivingRoomTest.ini pour les tests dans infrastructure
A36: Les tests valident le happy path et au moins un cas dégradé | K36: 1 | L36: Cas happy path: shouldEstablishConnectionWhenUrlIsValid dans stas.thermomether.domains.tests/DatabaseConnectorTests et shouldInsertTemperatureSuccessfully , shouldInsertTemperatureAlertSuccessfully,shouldInsertHumiditySuccessfully,shouldInsertHumidityAlertSuccessfully dans stas.thermomether.domains.tests/MesureDataMapperTests et shouldDisplayAndCheckTemperatureWhenCalculateAverageMeasurementWithMeasurements dans stas.thermomether.domains.tests/AgregateurTests Cas degradé : shouldThrowRepositoryExceptionWhenUrlIsInvalid dans stas.thermomether.domains.tests/DatabaseConnectorTests et shouldThrowExceptionWhenInsertTemperatureWithNullMeasure dans stas.thermomether.domains.tests/MesureDataMapperTests et shouldDoNothingWhenCalculateAverageMeasurementWithNoMeasurements dans stas.thermometer.domains.test.AgregateurTests
A37: Les tests réussissent sans adaptations | K37: 1
A38: Les tests sont rejouables sans modifications extérieures | K38: 1
A39: Acquis 5 : Tester en isolation | M39: Total Acquis 5 | N39: =SUM($K$41:$K44) -> 4 | O39: 4
A40: Seuil de réussite (tous sont à valider pour obtenir l'acquis)
A41: Les instructions des projets domains et présentations sont couvertes à 80% par des tests unitaires | K41: 1 | L41: - domains : 95% de lignes couvertes - presentations : 91% de lignes couvertes | Q41: Couverture de la partie domains = 95.25043177892918% couverture de la partie presentations = 91.42857142857143%
...

Sheet Eval 4
A1: Activité intégrative : itération 4
M2: Acquis évalués : | N2: AA 1 | O2: AA 2 | P2: AA 3 | Q2: AA 4 | R2: AA5
A3: Nom et prénom : | C3: Bouzia Badr | G3: Commande d'exécution de l'application : | K3: cd Stas.Monitor.App et puis dotnet run --config-file config.ini | M3: Statut (Observé=1, Pas observé=0) | N3: =IF($O$5=$N$5,TRUNC($N$14/$O$14),0) -> 1 | O3: =IF($O$5=$N$5,TRUNC($N$20/$O$20),0) -> 1 | P3: =IF($O$5=$N$5,TRUNC($N$27/$O$27),0) -> 1 | Q3: =IF($O$5=$N$5,TRUNC($N$33/$O$33),0) -> 1 | R3: =IF($O$5=$N$5,TRUNC($N$39/$O$39),0) -> 1
A4: Matricule : | C4: Q220251
A5: Préalable | K5: Observé (oui=1, non = 0) | L5: Justification de l'étudiant | M5: Total préalable | N5: =SUM($K$7:$K$12) -> 6 | O5: 6 | Q5: Retour de l'enseignant
A6: Tous ces éléments sont à observer pour que le travail soit évaluable
A7: Le projet Java ou la solution C# ont été mis à disposition à temps, selon les modalités prévues par l'énoncé (délais, règles relatives au dépôt distant, etc.) | K7: 1
A8: L'auto-évaluation est de qualité | K8: =IF(N8<=O8,1,0) -> 1 | M8: justifications manquantes ou imprécises | N8: 1 | O8: 3
A9: Le projet Java cible le JDK 17 et Gradle 8.+ Le projet C# cible .NET 6 et Avalonia 11+ | K9: 1
A10: Le dépôt distant peut être construit sans erreurs de compilation. Au besoin l'outil de construction résout les dépendances tierces. | K10: 1
A11: L'application utilise des ressources externes pour lire et sauver les données demandées. Ces ressources externes respectent les contraintes de l'énoncé (type de ressource, localisation, etc.) | K11: 1
A12: Les fonctionnalités requises sont implémentées et sufisamment de tests d'acceptation réussissent | K12: =IF(N12<=O12,1,0) -> 1 | L12: Toute les TA ont été implémentés | M12: TA non-observés : | N12: 3 | O12: 3 | Q12: Pour avoir les messages d'erreur lorsque tu fais dotnet run, il faut changer dans le csproj de App la propriété OutputType et la mettre à Exe AI-CS-02 : TA1 AI-CS-03 : TA1, TA4 | V12: AI-Java-6 : TA4 (fait ( couleur surchauffe et refroidissement) AI-Java-7 : TA1, TA2, TA3 ( j'ai changé le csproj en Exe (corrigé))
A14: Acquis 1 : Concevoir une solution selon les principes de l'orienté objet | K14: Observé | M14: Total Acquis 1 | N14: =SUM($K$16:$K$19) -> 4 | O14: 4
A15: Seuil de réussite (tous sont à valider pour obtenir l'acquis)
A16: Les méthodes sont peu complexes [ ] au plus 1 alerte NCSS dans les projets domains, presentations et infrastructures [ ] au plus 1 alerte CC dans les projets domains, presentations et infrastructures [ ] au plus 1 alerte TooManyParameter dans les projets domains, presentations et infrastructures | K16: 1 | L16: Aucune des ces alertes est présente dans le projet
A17: Déclarer des types avec une cohésion forte [ ] au plus 1 alerte LackOfCohesion dans les projets domains, presentations et infrastructures [ ] au plus 1 alerte TooManyFields max dans les projets domains, presentations et infrastructures [ ] au plus 1 alerte TooManyMethods max dans les projets domains, presentations et infrastructures | K17: 1 | L17: une alerte TooManyMethods dans Stas.Monitor.Presentations/MainPresenter.cs | Q17: HE0002 in Stas.Monitor.Presentations.MainPresenter.cs at line 7 until line 5 : MainPresenter has too many bodies. Expected 15. Actual 16.
A18: Déclarer des types avec un couplage faible [ ] 1 alerte AvoidNonPrivateInstanceField dans les projets domains, presentations et infrastructures [ ] 1 alerte CouplingBetweenObject dans les projets domains, presentations et infrastructures [ ] 1 alerte LooseCoupling max. dans les projets domains, presentations et infrastructures | K18: 1 | L18: Aucune de ses alertes n'est présente dans le projet
A19: Les types sont logiquement regroupés [ ] Pas d'alertes ArchUnit | K19: 1 | L19: Aucune alerte ArchUnit
A20: Acquis 2 : Programmer en exploitant les spécificités d'un langage de programmation | M20: Total Acquis 2 | N20: =SUM($K$23:$K$26) -> 4 | O20: 4
A21: Seuil de réussite (tous sont à valider pour obtenir l'acquis)
A22: Le code respecte les convention d'écriture du langage [ ] 5 alertes liées aux conventions d'écriture max. | K22: 1 | L22: Aucune alerte de convention d'écriture | Q22: Problème : SA1312 in Stas.Monitor.Views.AlertDifferenceDisplayConverter.cs at line 11 until line 33 : Variable 'AlertDifference' should begin with lower-case letter
A23: Le code exploite les pipeline de collections (stream en Java, Linq en C#) [ ] Au moins une utilisation pertinente de pipeline dans le code métier ou applicatif | K23: 1 | L23: J'utilise une linq dans Stas.Monitor.Presentations/MainPresenter.cs ligne 29
A24: Le code exploite la notion d'enregistrements [ ] Au moins un DTO ou Arguments d'événements est défini par un enregistrement | K24: 1 | L24: dans Stas.Monitor.Domains/CombinedHumidityDto.cs et Stas.Monitor.Domains/CombinedTemperatureDto.cs
A25: Le code exploite adéquatement les génériques [ ] Définition d'au moins un type générique [ ] Le type générique est utilisé avec deux arguments de type différents. | K25: 1 | L25: /
A26: Le code exploite les références de méthode [ ] Java déclaration d'au moins un membre de type interface fonctionnelle et initialisation [ ] C# déclaration d'au moins un membre event | K26: 1 | L26: je declare pas directement un membre event mais j'utilise les évenement via : Stas.Monitor.Presentations/MainPresenter.cs et Stas.Monitor.Views/MainWindow.axaml.cs ( la ou les évenement sont gérés ( code behind et interface))
A27: Acquis 3 : Exploiter des ressources externes | M27: Total Acquis 3 | N27: =SUM($K$29:$K32) -> 4 | O27: 4
A28: Seuil de réussite (tous sont à valider pour obtenir l'acquis)
A29: Les ressources acquises sont effectivement libérées [ ] Pas d'alerte AvoidFileStream [ ] Pas d'alerte UseTryWithResources [ ] Pas d'alerte CloseResource | K29: 1 | L29: Aucune des ces alertes est présente dans le projet
A30: Les exceptions spécifiques aux ressources utilisées sont attrapées et traitées [ ] Pas d'alerte EmptyCatchBlock [ ] Pas d'alerte EmptyFinallyBlock [ ] Pas d'alerte EmptyTryBlock [ ] Pas d'alerte AvoidRethrowingException [ ] Pas d'alerte AvoidRethrowingNewInstanceOfTheSameException | K30: 1 | L30: Aucune des ces alertes est présente dans le projet
A31: Les transactions manuelles sont correctement mises en places aux endroits nécessaires [ ] La transaction est commencée [ ] La transaction est validée en cas de succès (commit) [ ] La transaction est annulée en cas d'échec (rollback) [ ] La transaction est utilisée pour soumettre plusieurs requêtes modifiant la BD | K31: 1 | L31: il y'a pas de transactions uniquement des select voici la classe : Stas.Monitor.Infrastructures/MeasurementSql.cs
A32: Le cas échéant les requêtes SQL sont paramétrés adéquatement [ ] les arguments des requêtes SQL utilisent les méthodes adéquates pour être injectés dans la requête. [ ] les types des arguments sont adéquat par rapport au type de la colonne et inversement. | K32: 1 | L32: dans Stas.Monitor.Infrastructures/MeasurementSql.cs ligne 11 a 21 , ligne 28 a 38 , ligne 50 a 71 et ligne 85 a 106 ( tout est respecté)
A33: Acquis 4 : Tester en intégration | M33: Total Acquis 4 | N33: =SUM($K$35:$K39) -> 4 | O33: 4
A34: Seuil de réussite (tous sont à valider pour obtenir l'acquis)
A35: Des ressources spécifiques à l'environnement de test sont utilisées | K35: 1 | L35: j'utilise une base de donnée de mémoire pour mon test present dans : Stas.Monitor.Infrastructures.Tests/MeasurementSqlTests.cs
A36: Les tests valident le happy path et au moins un cas dégradé | K36: 1 | L36: dans Stas.Monitor.Infrastructures.Tests/MeasurementSqlTests.cs:happy path : Should_GetLatestTemperatureTimestamp_ForGivenThermometer() , Should_GetLatestHumidityTimestamp_ForGivenThermometer() , Should_GetCombinedTemperatureData_ForGivenThermometerAndDuration() et Should_GetCombinedHumidityData_ForGivenThermometerAndDuration() et dans Stas.Monitor.Presentations.Tests/MainPresenterTests.cs UpdateMeasurements_ShouldFetchTemperatureData() et UpdateMeasurementsHumidity_ShouldFetchHumidityData() et Setting_SelectedThermometerName_ShouldTriggerUpdateMeasurements() et Toggling_ShowTemperatureMeasurements_ShouldTriggerVisibilityToggle(). Pour les cas degradés : Stas.Monitor.Infrastructures.Tests/MeasurementSqlTests.cs Should_ReturnMinValue_ForNonExistentThermometer() et Should_ReturnEmpty_ForNegativeDurationInCombinedTemperatureData() et Should_ReturnEmpty_ForNegativeDurationInCombinedHumidityData() et dans Stas.Monitor.Presentations.Tests/MainPresenterTests.cs Changing_SelectedDurationTime_ShouldNotUpdateMeasurements()
A37: Les tests réussissent sans adaptations | K37: 1
A38: Les tests sont rejouables sans modifications extérieures | K38: 1
A39: Acquis 5 : Tester en isolation | M39: Total Acquis 5 | N39: =SUM($K$41:$K44) -> 4 | O39: 4
A40: Seuil de réussite (tous sont à valider pour obtenir l'acquis)
A41: Les instructions des projets domains et présentations sont couvertes à 80% par des tests unitaires | K41: 1 | L41: - domains : 100% de lignes couvertes - presentations : 80% de lignes couvertes | Q41: Couverture de la partie domains = 100.0% couverture de la partie presentations = 80.98591549295774%
...

Sheet recapitulatif 1s
A1: Étudiant | B1: Nom et prénom
B3: AA1 | C3: AA2 | D3: AA3 | E3: AA4 | F3: AA5 | G3: Observations/It
A4: Eval 3 | B4: ='Eval 3'!N3 -> 0 | C4: ='Eval 3'!O3 -> 0 | D4: ='Eval 3'!P3 -> 0 | E4: ='Eval 3'!Q3 -> 0 | F4: ='Eval 3'!R3 -> 0 | G4: =SUM($B4:$F4) -> 0
A5: Eval 4 | B5: ='Eval 4'!N3 -> 1 | C5: ='Eval 4'!O3 -> 1 | D5: ='Eval 4'!P3 -> 1 | E5: ='Eval 4'!Q3 -> 1 | F5: ='Eval 4'!R3 -> 1 | G5: =SUM($B5:$F5) -> 5
A6: Défense orale | B6: 0 | C6: 0 | D6: 0 | E6: 0 | F6: 0 | G6: =SUM($B6:$F6) -> 0
A7: Observations/AA | B7: =SUM(B$4:B$6) -> 1 | C7: =SUM(C$4:C$6) -> 1 | D7: =SUM(D$4:D$6) -> 1 | E7: =SUM(E$4:E$6) -> 1 | F7: =SUM(F$4:F$6) -> 1 | G7: =SUM($B7:$F7) -> 5
A9: Note sans adaptations | G9: =IF(G7<10,G7,10+SUM('Eval 3'!K47:K56,'Eval 4'!K47:K56)/2) -> 5
A10: Adaptations de l'enseignant | G10: 0
A11: Note adaptée | G11: =G9+G10 -> 5
